Workbook
Name circ: #REF!
Name scen: #REF!

Sheet Cover >>>
C15: DIASORIN
C16: Valuation

Sheet Inputs >>>
C16: Financial Model
C17: Inputs

Sheet AFS
A1: Company Fundamentals - Income Statement
A2: Company Name | K2: DiaSorin SpA (DIAS.MI)
A3: Country of Exchange | K3: Italy
A4: Country of Headquarters | K4: Italy
A5: TRBC Industry Group | K5: Healthcare Equipment & Supplies
A6: CF Template | K6: IND
A7: Consolidation Basis | K7: Consolidated
A8: Scaling | K8: Millions
A9: Period | K9: Annual
A10: Export Date | K10: 46050.798
A11: Statement Data | B11: 2015 | C11: 2016 | D11: 2017 | E11: 2018 | F11: 2019 | G11: 2020 | H11: 2021 | I11: 2022 | J11: 2023 | K11: 2024
A12: Period End Date | B12: 42369 | C12: 42735 | D12: 43100 | E12: 43465 | F12: 43830 | G12: 44196 | H12: 44561 | I12: 44926 | J12: 45291 | K12: 45657
A13: Statement Date | B13: 42369 | C13: 42735 | D13: 43100 | E13: 43465 | F13: 43830 | G13: 44196 | H13: 44561 | I13: 44926 | J13: 45291 | K13: 45657
A14: Standardized Currency | B14: EUR | C14: EUR | D14: EUR | E14: EUR | F14: EUR | G14: EUR | H14: EUR | I14: EUR | J14: EUR | K14: EUR
A15: Template Type | B15: Industrial - Gross Profit | C15: Industrial - Gross Profit | D15: Industrial - Gross Profit | E15: Industrial - Gross Profit | F15: Industrial - Gross Profit | G15: Industrial - Gross Profit | H15: Industrial - Gross Profit | I15: Industrial - Gross Profit | J15: Industrial - Gross Profit | K15: Industrial - Gross Profit
A17: Income Statement - Standardized (Currency: Euro)
A18: Field Name | B18: 31-12-2015 | C18: 31-12-2016 | D18: 31-12-2017 | E18: 31-12-2018 | F18: 31-12-2019 | G18: 31-12-2020 | H18: 31-12-2021 | I18: 31-12-2022 | J18: 31-12-2023 | K18: 31-12-2024
A19: Revenues
A20: Revenue from Goods & Services | B20: 499.18 | C20: 569.31 | D20: 637.49 | E20: 669.2 | F20: 706.32 | G20: 881.31 | H20: 1237.65 | I20: 1361.14 | J20: 1148.21 | K20: 1185.43
A21: Sales of Goods & Services - Net - Unclassified | B21: 499.18 | C21: 569.31 | D21: 637.49 | E21: 669.2 | F21: 706.32 | G21: 881.31 | H21: 1237.65 | I21: 1361.14 | J21: 1148.21 | K21: 1185.43
A22: Revenue from Business Activities - Total | B22: 499.18 | C22: 569.31 | D22: 637.49 | E22: 669.2 | F22: 706.32 | G22: 881.31 | H22: 1237.65 | I22: 1361.14 | J22: 1148.21 | K22: 1185.43
A23: Operating Expenses
A24: Cost of Operating Revenue | B24: 157.28 | C24: 180.16 | D24: 205.59 | E24: 213.43 | F24: 217.63 | G24: 278.4 | H24: 412.88 | I24: 460.53 | J24: 407.02 | K24: 403.73
A25: Cost of Revenues - Total | B25: 157.28 | C25: 180.16 | D25: 205.59 | E25: 213.43 | F25: 217.63 | G25: 278.4 | H25: 412.88 | I25: 460.53 | J25: 407.02 | K25: 403.73
A26: Cost of Revenues - Unclassified | B26: 139.63 | C26: 161.69 | D26: 187.82 | E26: 196.75 | F26: 201.18 | G26: 260.56 | H26: 393.39 | I26: 436.85 | J26: 385.54 | K26: 383.98
A27: Amortization in Cost of Revenues | B27: 17.65 | C27: 18.47 | D27: 17.77 | E27: 16.68 | F27: 16.45 | G27: 17.84 | H27: 19.49 | I27: 23.67 | J27: 21.49 | K27: 19.75
A28: Gross Profit - Industrials/Property - Total | B28: 341.9 | C28: 389.15 | D28: 431.9 | E28: 455.77 | F28: 488.69 | G28: 602.91 | H28: 824.77 | I28: 900.61 | J28: 741.19 | K28: 781.7
A29: Selling, General & Administrative Expenses - Total | B29: 183.55 | C29: 211.97 | D29: 233.01 | E29: 247.22 | F29: 262.37 | G29: 269.83 | H29: 380.24 | I29: 518.4 | J29: 505.4 | K29: 510.44
A30: Selling, General & Administrative Expenses - Unclassified | B30: 153.54 | C30: 169.51 | D30: 187.87 | E30: 195.49 | F30: 205.33 | G30: 208.14 | H30: 296.24 | I30: 406.74 | J30: 406.25 | K30: 407.62
A31: Labor & Related Expenses including Stock-Based Compensation in Selling, General & Administrative Expenses | E31: 4.79 | F31: 7.02 | G31: 8 | H31: 8.37 | I31: 8.01 | J31: 8.16 | K31: 8.15
A32: Research & Development Expense | B32: 24.03 | C32: 32.42 | D32: 37.64 | E32: 39.63 | F32: 41.75 | G32: 43.12 | H32: 57.49 | I32: 78.7 | J32: 69.09 | K32: 72.39
A33: Amortization of Intangibles in Selling, General & Administrative Expenses | B33: 2.13 | C33: 5.29 | D33: 5.98 | E33: 5.45 | F33: 6.2 | G33: 7.68 | H33: 12.61 | I33: 18.2 | J33: 21.86 | K33: 19.18
A34: Selling, General & Administrative Expenses - Other - Total | B34: 3.85 | C34: 4.74 | D34: 1.51 | E34: 1.86 | F34: 2.08 | G34: 2.88 | H34: 5.54 | I34: 6.75 | J34: 0.04 | K34: 3.1
A35: Property & Other Taxes | E35: 0.75 | F35: 0.94 | G35: 0.8 | H35: 1.41 | I35: 1.37 | J35: 1.7 | K35: 1.81
A36: Provision for Doubtful Accounts & Write-off | B36: 3.85 | C36: 4.74 | D36: 1.51 | E36: 1.11 | F36: 1.14 | G36: 2.08 | H36: 4.13 | I36: 5.38 | J36: -1.66 | K36: 1.29
A37: Other Operating Expense/(Income) - Net | B37: 2.28 | C37: -0.75 | D37: 1.33 | E37: -1.3 | F37: 3.86 | G37: 2.97 | H37: 3.13 | I37: 6.89 | J37: -2.06 | K37: 6.22
A38: Other Operating Expense | G38: 0 | K38: 0
A39: Operating Provisions - Increase/(Decrease) | E39: -1.3 | F39: 3.86 | G39: 2.97 | H39: 3.13 | I39: 6.89 | J39: -2.06 | K39: 6.22
A40: Operating Expenses - Total | B40: 343.11 | C40: 391.37 | D40: 439.93 | E40: 459.35 | F40: 483.86 | G40: 551.19 | H40: 796.25 | I40: 985.82 | J40: 910.36 | K40: 920.38
A41: Operating Profit
...

Sheet AFS2
I2: HISTORICAL (ACTUALS) | K2: FORECAST (MEAN)
B3: FY Dec-17 | C3: FY Dec-18 | D3: FY Dec-19 | E3: FY Dec-20 | F3: FY Dec-21 | G3: FY Dec-22 | H3: FY Dec-23 | I3: FY Dec-24 | K3: FY Dec-25 | L3: FY Dec-26 | M3: FY Dec-27 | N3: FY Dec-28 | O3: FY Dec-29
A4: REVENUE | B4: 637.5 | C4: 669.2 | D4: 706.3 | E4: 881.305 | F4: 1237.7 | G4: 1361.1 | H4: 1148 | I4: 1185 | K4: 1203.7806 | L4: 1275.5036 | M4: 1375.6088 | N4: 1463.3333 | O4: 1563
A5: COST OF GOODS SOLD | B5: 205.6 | C5: 213.4 | D5: 217.6 | E5: 278.4 | F5: 412.9 | G5: 460.5 | H5: 407 | I5: 403.726 | K5: 424 | L5: 445.5 | M5: 475.5 | N5: 512 | O5: 546
A6: GROSS INCOME | B6: 431.9 | C6: 455.8 | D6: 488.7 | E6: 602.905 | F6: 824.8 | G6: 900.6 | H6: 741 | I6: 781.701 | K6: 782.33333 | L6: 813 | M6: 866 | N6: 946 | O6: 1018
A7: GROSS PROFIT MARGIN | B7: 0.677 | C7: 0.6811 | D7: 0.6919 | E7: 0.6841 | F7: 0.6664 | G7: 0.6616 | H7: 0.6454 | I7: 0.6594 | K7: 0.6494567 | L7: 0.6478 | M7: 0.6474 | N7: 0.646 | O7: 0.65
A9: R&D EXPENSE | B9: 43.6 | C9: 45.1 | D9: 41.752 | E9: 50.8 | F9: 70.1 | G9: 78.702 | H9: 69.09 | I9: 91.567 | K9: 92 | L9: 95 | M9: 99 | N9: 106 | O9: 114
A10: SELLING & MARKETING EXPENSE | B10: 123.2 | C10: 133.1 | D10: 142.8 | E10: 144.064 | F10: 211.3 | G10: 292.05 | H10: 286 | I10: 287.748 | K10: 287 | L10: 296 | M10: 308 | N10: 330 | O10: 357
A11: GENERAL & ADMIN EXPENSE | B11: 64.7 | C11: 67.2 | D11: 69.6 | E11: 72.083 | F11: 93.299 | G11: 122.7 | H11: 129 | I11: 128.023 | K11: 122 | L11: 123.5 | M11: 127 | N11: 132 | O11: 136
A12: SG&A EXPENSE | B12: 187.9 | C12: 200.3 | D12: 205.328 | E12: 216.147 | F12: 304.6 | G12: 406.737 | H12: - | I12: - | K12: 131 | L12: 133 | M12: 134 | N12: - | O12: -
A14: EBITDA | B14: 237.922 | C14: 255.4 | D14: 276.8 | E14: 385.26 | F14: 543.1 | G14: 514.2 | H14: 375 | I14: 394 | K14: 393.05854 | L14: 426.75162 | M14: 469.09458 | N14: 480 | O14: 546.5
A15: EBITDA MARGIN | B15: - | C15: - | D15: - | E15: - | F15: - | G15: - | H15: - | I15: 0.33247 | K15: 0.334 | L15: 0.34 | M15: 0.3485714 | N15: 0.356 | O15: 0.354
A16: EBITDA PER SHARE | B16: - | C16: - | D16: - | E16: 7.04 | F16: 9.43 | G16: 9.41 | H16: 7.04 | I16: 7.049 | K16: 6.6 | L16: 7.22 | M16: 7.895 | N16: 8.655 | O16: 10.28
A17: DEPRECIATION & AMORTIZATION | B17: 69.609 | C17: 50.826 | D17: 58.972 | E17: 61.034 | F17: 115.506 | G17: 137.546 | H17: 158.371 | I17: 148.79 | K17: 133.35833 | L17: 137.34333 | M17: 141.65167 | N17: 141.465 | O17: 140.5
A18: DEPRECIATION | B18: 29.666 | C18: 28.97 | D18: 35.132 | E18: 33.558 | F18: 47.131 | G18: 60.404 | H18: 61.829 | I18: 53.871 | K18: 78.70225 | L18: 84.127 | M18: 91.3055 | N18: 82.7475 | O18: 77.013
A19: AMORTIZATION | B19: - | C19: 21.855 | D19: 23.84 | E19: 27.476 | F19: - | G19: 40.142 | H19: 10.919 | I19: 94.919 | K19: 88.88233 | L19: 86.526 | M19: 86.448 | N19: 63.1055 | O19: 61.133
A20: EBITA | B20: 208.236 | C20: 226.355 | D20: 241.74 | E20: 351.702 | F20: - | G20: 457.163 | H20: 192 | I20: - | K20: 276.5 | L20: 297.66667 | M20: 333 | N20: 320 | O20: -
A22: EBIT | B22: 184.4 | C22: 204.5 | D22: 217.9 | E22: 324.226 | F22: 465.1 | G22: 417.021 | H22: 216 | I22: 258 | K22: 275.15015 | L22: 303.63631 | M22: 345.33931 | N22: 357 | O22: 406
A23: EBIT MARGIN | B23: - | C23: - | D23: - | E23: - | F23: - | G23: - | H23: - | I23: 0.2177 | K23: 0.2235 | L23: 0.2373333 | M23: 0.2506667 | N23: 0.264 | O23: 0.2655
A24: INTEREST EXPENSE | B24: 5.7 | C24: 0.2 | D24: 3.517 | E24: 2.9 | F24: 20.2 | G24: 34.072 | H24: 15 | I24: 28.801 | K24: 17 | L24: 15.26 | M24: 12.88 | N24: 10 | O24: 7
A25: OTHER INCOME/EXPENSE | B25: - | C25: - | D25: - | E25: - | F25: - | G25: - | H25: - | I25: - | K25: 17 | L25: 18 | M25: 18 | N25: 17 | O25: 17
A27: PRE-TAX PROFIT | B27: 178.7 | C27: 204.4 | D27: 216.3 | E27: 321.373 | F27: 399.3 | G27: 325.9 | H27: 201 | I27: 242.448 | K27: 272.38578 | L27: 289.99944 | M27: 325.347 | N27: 342.5 | O27: 427
A28: TAX PROVISION | B28: 38.8 | C28: 46.2 | D28: 40.6 | E28: 73.077 | F28: 88.6 | G28: 85.8 | H28: 42 | I28: 55.391 | K28: 58.075 | L28: 67.35 | M28: 77.9 | N28: 87 | O28: 94.5
A29: TAX RATE | B29: 0.2171237 | C29: 0.2259 | D29: 0.1877023 | E29: 0.2274424 | F29: 0.2218883 | G29: 0.2632709 | H29: 0.2089552 | I29: 0.2272727 | K29: 0.2455143 | L29: 0.246 | M29: 0.2422857 | N29: 0.235 | O29: 0.25
A31: NET INCOME | B31: 139.9 | C31: 158.1 | D31: 175.7 | E31: 248.3 | F31: 310.7 | G31: 240.1 | H31: 159 | I31: 187 | K31: 210.032 | L31: 233.67567 | M31: 266.1495 | N31: 281.33333 | O31: 323
A32: NET INCOME MARGIN | B32: - | C32: - | D32: - | E32: - | F32: - | G32: - | H32: - | I32: 0.15699 | K32: 0.1761667 | L32: 0.1878 | M32: 0.2 | N32: 0.218 | O32: 0.205
A34: EARNINGS PER SHARE | B34: 2.54 | C34: 2.85 | D34: 3.2 | E34: 4.5 | F34: 5.4 | G34: 4.392 | H34: 2.98 | I34: 3.342 | K34: 3.5505 | L34: 4.0372 | M34: 4.64836 | N34: 4.66 | O34: 5.3
A35: CASH EPS | B35: - | C35: - | D35: - | E35: - | F35: - | G35: - | H35: - | I35: 6.01 | K35: 5.745 | L35: 6.116 | M35: 6.595 | N35: - | O35: -
A36: EBITDA REPORTED | B36: 237.922 | C36: 255.4 | D36: 276.8 | E36: 385.26 | F36: 556.907 | G36: 536.542 | H36: 375 | I36: 387.366 | K36: 389.74667 | L36: 426.08833 | M36: 475.54 | N36: 497.34 | O36: 546.5
A37: PRE-TAX PROFIT REPORTED | B37: 178.7 | C37: 204.4 | D37: 216.3 | E37: 321.373 | F37: 399.3 | G37: 325.9 | H37: 201 | I37: 242.448 | K37: 250.5545 | L37: 282.39475 | M37: 325.7395 | N37: 350 | O37: 387
A38: NET INCOME REPORTED | B38: 139.9 | C38: 158.1 | D38: 175.7 | E38: 248.3 | F38: 310.7 | G38: 240.1 | H38: 159 | I38: 187 | K38: 177.32571 | L38: 207.82257 | M38: 243.33443 | N38: 262 | O38: 290
A39: EARNINGS PER SHARE REPORTED | B39: 2.54 | C39: 2.85 | D39: 3.2 | E39: 4.5 | F39: 5.4 | G39: 4.392 | H39: 2.98 | I39: 3.342 | K39: 3.31711 | L39: 3.9299 | M39: 4.48589 | N39: 4.79 | O39: 5.3
A40: DIVIDEND PER SHARE | B40: 0.85 | C40: 0.9 | D40: 0.9 | E40: 0.95 | F40: 1.05 | G40: 1.1 | H40: 1.15 | I40: 1.15 | K40: 1.2024 | L40: 1.28333 | M40: 1.3685 | N40: 1.47667 | O40: 1.535
A41: NUMBER OF SHARES OUTSTANDING | B41: 53.56836 | C41: 55.51311 | D41: 54.712 | E41: 54.758 | F41: 57.58667 | G41: 54.665 | H41: 53.289 | I41: 55.86871 | K41: 55.78 | L41: 55.066 | M41: 55.066 | N41: 53.69 | O41: 55
A42: NET INTEREST EXPENSES (INCOME) | B42: - | C42: - | D42: - | E42: - | F42: - | G42: - | H42: - | I42: - | K42: 14 | L42: 10 | M42: 6 | N42: 2 | O42: 7
K44: =K50/I50-1 -> 0.014850586 | L44: =L50/K50-1 -> 0.040399523 | M44: =M50/L50-1 -> 0.048431007 | N44: =N50/M50-1 -> 0.0087011972 | O44: =O50/N50-1 -> 0.077138471
B45: FY Dec-17 | C45: FY Dec-18 | D45: FY Dec-19 | E45: FY Dec-20 | F45: FY Dec-21 | G45: FY Dec-22 | H45: FY Dec-23 | I45: FY Dec-24 | K45: FY Dec-25 | L45: FY Dec-26 | M45: FY Dec-27 | N45: FY Dec-28 | O45: FY Dec-29
A46: CASH AND CASH EQUIVALENTS | B46: 159.34 | C46: 73.1 | D46: 157.552 | E46: 339.881 | F46: 403.02 | G46: 241.776 | H46: 280.314 | I46: 344.27 | K46: 423 | L46: 560.5 | M46: 720.75 | N46: 735.66667 | O46: 1006
A47: INVENTORY | B47: 142.802 | C47: 160.396 | D47: 171.127 | E47: 191.234 | F47: 298.049 | G47: 306.503 | H47: 315.5 | I47: 344.043 | K47: 319 | L47: 340.25 | M47: 365.25 | N47: 388 | O47: 409.5
A48: CURRENT ASSETS | B48: 481.241 | C48: 414.86 | D48: 530.761 | E48: 713.917 | F48: 958.291 | G48: 1028.94 | H48: 982.692 | I48: 967.181 | K48: 1039 | L48: 1178.6667 | M48: 1355.3333 | N48: 1260.5 | O48: 1344
...

Sheet AFS3
A1: DiaSorin S.p.A. (DIA-IT)
B2: DEC '15 | C2: DEC '16 | D2: DEC '17 | E2: DEC '18 | F2: DEC '19 | G2: DEC '20 | H2: DEC '21 | I2: DEC '22 | J2: DEC '23 | K2: DEC '24
A3: Sales | B3: 499.181 | C3: 569.312 | D3: 637.487 | E3: 669.197 | F3: 706.319 | G3: 881.305 | H3: 1237.654 | I3: 1361.138 | J3: 1148.21 | K3: 1185.427
A4: Cost of Goods Sold (COGS) incl. D&A | B4: 165.674 | C4: 198.729 | D4: 225.094 | E4: 234.956 | F4: 244.163 | G4: 298.932 | H4: 455.587 | I4: 534.632 | J4: 479.127 | K4: 477.909
A5: COGS excluding D&A | B5: 132.69 | C5: 154.022 | D5: 179.243 | E5: 189.581 | F5: 191.387 | G5: 240.119 | H5: 372.181 | I5: 415.288 | J5: 364.101 | K5: 348.868
A6: Depreciation & Amortization Expense | B6: 32.984 | C6: 44.707 | D6: 45.851 | E6: 45.375 | F6: 52.776 | G6: 58.813 | H6: 83.406 | I6: 119.344 | J6: 115.026 | K6: 129.041
A7: Depreciation | B7: 24.875 | C7: 27.141 | D7: 29.666 | E7: 28.531 | F7: 35.132 | G7: 33.558 | H7: 47.131 | I7: 60.404 | J7: 61.829 | K7: 53.871
A8: Amortization of Intangibles | B8: 8.109 | C8: 17.566 | D8: 16.185 | E8: 16.844 | F8: 17.644 | G8: 25.255 | H8: 36.275 | I8: 58.94 | J8: 53.197 | K8: 75.17
A9: Gross Income | B9: 333.507 | C9: 370.583 | D9: 412.393 | E9: 434.241 | F9: 462.156 | G9: 582.373 | H9: 782.067 | I9: 826.506 | J9: 669.083 | K9: 707.518
A10: SG&A Expense | B10: 175.134 | C10: 189.567 | D10: 211.997 | E10: 223.828 | F10: 233.516 | G10: 247.628 | H10: 332.827 | I10: 438.599 | J10: 433.175 | K10: 426.764
A11: Research & Development | B11: 23.889 | C11: 31.519 | D11: 41.999 | E11: 42.542 | F11: 45.616 | G11: 50.8 | H11: 63.385 | I11: 93.146 | J11: 89.71 | K11: 68.458
A12: Other SG&A | B12: 151.245 | C12: 158.048 | D12: 169.998 | E12: 181.286 | F12: 187.9 | G12: 196.828 | H12: 269.442 | I12: 345.453 | J12: 343.465 | K12: 358.306
A13: Other Operating Expense | B13: 2.008 | C13: 5.337 | D13: 2.208 | E13: 1.861 | F13: 2.317 | G13: 1.667 | H13: 4.707 | I13: 5.691 | J13: 0.12 | K13: 3.102
A14: EBIT (Operating Income) | B14: 156.365 | C14: 175.679 | D14: 198.188 | E14: 208.552 | F14: 226.323 | G14: 333.078 | H14: 444.533 | I14: 382.216 | J14: 235.788 | K14: 277.652
... A20: Unusual Expense - Net | B20: 2.108 | C20: 5.426 | D20: 12.022 | E20: 1.709 | F20: 4.615 | G20: 5.885 | H20: 21.902 | I20: 20.025 | J20: 11.814 | K20: 6.391
A21: Impairments | G21: 2.222 | H21: 0 | I21: 9.039 | J21: 4.404 | K21: 0
A22: Other Intangibles | D22: 0 | E22: 0 | F22: 0 | G22: 0 | H22: 0 | I22: 9.039 | J22: 4.404 | K22: 0
A23: Property,Plant & Equipment | G23: 2.222 | H23: 0
A24: Restructuring Expense | B24: 2.108 | C24: 5.426 | D24: 12.022 | E24: 0 | F24: 0 | G24: 0 | H24: 21.902 | I24: 15.023 | J24: 8.847 | K24: 6.391
A25: Unrealized Valuation Gain/Loss | E25: 2.43 | F25: 0 | I25: 4.037 | J25: 1.437
A26: Hedges/Derivatives | I26: 4.037 | J26: 1.437
A27: Other Intangibles | E27: 2.43 | F27: 0
A28: Excpl Chrgs - Others | E28: 4.139 | F28: 4.615 | G28: 3.663
A29: Other Unusual Expense | B29: 2.108 | E29: 4.139 | F29: 4.615 | G29: 3.663
A30: Pretax Income | B30: 150.533 | C30: 168.751 | D30: 179.11 | E30: 204.508 | F30: 216.402 | G30: 321.373 | H30: 399.335 | I30: 325.94 | J30: 201.216 | K30: 242.448
A31: Income Taxes | B31: 49.554 | C31: 55.578 | D31: 38.828 | E31: 46.235 | F31: 40.552 | G31: 73.077 | H31: 88.603 | I31: 85.83 | J31: 42.708 | K31: 55.391
A32: Income Taxes - Current Domestic | B32: 50.462 | C32: 57.557 | D32: 37.575 | E32: 43.034 | F32: 48.857 | G32: 71.355 | H32: 90.201 | I32: 62.842 | J32: 55.695 | K32: 63.332
A33: Income Taxes - Deferred Domestic | B33: -0.908 | C33: -1.979 | D33: 1.253 | E33: 3.201 | F33: -8.305 | G33: 1.722 | H33: -1.598 | I33: 22.988 | J33: -12.987 | K33: -7.941
A34: Equity in Earnings of Affiliates | B34: -0.431 | C34: -0.555 | D34: -0.404 | E34: -0.143 | F34: -0.115 | K34: 0
A35: Consolidated Net Income | B35: 100.548 | C35: 112.618 | D35: 139.878 | E35: 158.13 | F35: 175.735 | G35: 248.296 | H35: 310.732 | I35: 240.11 | J35: 158.508 | K35: 187.057
A36: Minority Interest | B36: 0.128 | C36: 0.235 | D36: 0 | E36: 0.002 | F36: 0 | G36: 0.425 | H36: -0.236 | I36: -0.797 | J36: -1.341 | K36: -1.048
A37: Net Income | B37: 100.42 | C37: 112.383 | D37: 139.878 | E37: 158.128 | F37: 175.735 | G37: 247.871 | H37: 310.968 | I37: 240.907 | J37: 159.849 | K37: 188.105
A38: Net Income available to Common | B38: 100.42 | C38: 112.383 | D38: 139.878 | E38: 158.128 | F38: 175.735 | G38: 247.871 | H38: 310.968 | I38: 240.907 | J38: 159.849 | K38: 188.105
A39: Per Share
A40: EPS (recurring) | B40: 1.856579 | C40: 2.108946 | D40: 2.69637 | E40: 2.87003 | F40: 3.258825 | G40: 4.574788 | H40: 5.666232 | I40: 4.391473 | J40: 3.015804 | K40: 3.429673
A41: EPS (basic) | B41: 1.83 | C41: 2.05 | D41: 2.54 | E41: 2.8485 | F41: 3.212 | G41: 4.5267 | H41: 5.4443 | I41: 4.1715 | J41: 2.8675 | K41: 3.3669
A42: Basic Shares Outstanding | B42: 54.883529 | C42: 54.849893 | D42: 54.997425 | E42: 55.513113 | F42: 54.711844 | G42: 54.757637 | H42: 57.117998 | I42: 57.75085 | J42: 55.745935 | K42: 55.868709
A43: Total Shares Outstanding | B43: 54.978307 | C43: 54.758307 | D43: 55.3994 | E43: 54.65725 | F43: 54.790656 | G43: 54.722145 | H43: 54.746257 | I43: 53.512885 | J43: 53.359979 | K43: 53.891959
A44: EPS (diluted) | B44: 1.83 | C44: 2.04 | D44: 2.54 | E44: 2.8485 | F44: 3.2 | G44: 4.5 | H44: 5.4 | I44: 4.15 | J44: 2.8675 | K44: 3.35
A45: Diluted Shares Outstanding | B45: 54.883529 | C45: 55.089706 | D45: 54.997425 | E45: 55.513113 | F45: 54.917187 | G45: 55.082444 | H45: 57.586667 | I45: 58.04988 | J45: 55.745935 | K45: 56.150746
...

Sheet Restatements
A1: Restated Financial Statements
C3: Historicals
B4: USD: mln | C4: 2015 | D4: 2016 | E4: 2017 | F4: 2018 | G4: 2019 | H4: 2020 | I4: 2021 | J4: 2022 | K4: 2023 | L4: 2024 | XFC4: =XFB4+365 -> 365
B6: Income statement
B8: Revenues from the sale of goods and services | C8: =AFS!B20 -> 499.18 | D8: =AFS!C20 -> 569.31 | E8: =AFS!D20 -> 637.49 | F8: =AFS!E20 -> 669.2 | G8: =AFS!F20 -> 706.32 | H8: =AFS!G20 -> 881.31 | I8: =AFS!H20 -> 1237.65 | J8: =AFS!I20 -> 1361.14 | ... L8: =AFS!K20 -> 1185.43
B9: Growth | C9: n.a. | D9: n.a. | E9: n.a. | F9: n.a. | G9: n.a. | H9: n.a. | I9: n.a. | J9: n.a. | K9: n.a. | L9: n.a.
B10: COGS | C10: =AFS!B24 -> 157.28 | D10: =AFS!C24 -> 180.16 | E10: =AFS!D24 -> 205.59 | F10: =AFS!E24 -> 213.43 | G10: =AFS!F24 -> 217.63 | H10: =AFS!G24 -> 278.4 | I10: =AFS!H24 -> 412.88 | J10: =AFS!I24 -> 460.53 | ... L10: =AFS!K24 -> 403.73
B11: SGA | C11: =AFS!B29-AFS!B136 -> 132.91 | D11: =AFS!C29-AFS!C136 -> 148.79 | E11: =AFS!D29-AFS!D136 -> 163.4 | F11: =AFS!E29-AFS!E136 -> 179.71 | G11: =AFS!F29-AFS!F136 -> 186.95 | H11: =AFS!G29-AFS!G136 -> 193.18 | I11: =AFS!H29-AFS!H136 -> 264.73 | J11: =AFS!I29-AFS!I136 -> 357.18 | ... L11: =AFS!K29-AFS!K136 -> 361.65
B12: Other | C12: =AFS!B37 -> 2.28 | D12: =AFS!C37 -> -0.75 | E12: =AFS!D37 -> 1.33 | F12: =AFS!E37 -> -1.3 | G12: =AFS!F37 -> 3.86 | H12: =AFS!G37 -> 2.97 | I12: =AFS!H37 -> 3.13 | J12: =AFS!I37 -> 6.89 | ... L12: =AFS!K37 -> 6.22
B13: Total operating expenses | C13: =C10+C12+C11 -> 292.47 | D13: =D10+D12+D11 -> 328.2 | E13: =E10+E12+E11 -> 370.32 | F13: =F10+F12+F11 -> 391.84 | G13: =G10+G12+G11 -> 408.44 | H13: =H10+H12+H11 -> 474.55 | I13: =I10+I12+I11 -> 680.74 | J13: =J10+J12+J11 -> 824.6 | ... L13: =L10+L12+L11 -> 771.6
B14: EBITDA | C14: =C8-C13 -> 206.71 | D14: =D8-D13 -> 241.11 | E14: =E8-E13 -> 267.17 | F14: =F8-F13 -> 277.36 | G14: =G8-G13 -> 297.88 | H14: =H8-H13 -> 406.76 | I14: =I8-I13 -> 556.91 | J14: =J8-J13 -> 536.54 | ... L14: =L8-L13 -> 413.83
B15: Margin | C15: =C14/C8 -> 0.41409912 | D15: =D14/D8 -> 0.42351267 | E15: =E14/E8 -> 0.41909677 | F15: =F14/F8 -> 0.41446503 | G15: =G14/G8 -> 0.42173519 | H15: =H14/H8 -> 0.46154021 | I15: =I14/I8 -> 0.44997374 | J15: =J14/J8 -> 0.39418429 | ... L15: =L14/L8 -> 0.34909695
B16: Depreciation | C16: =AFS!B136 -> 50.64 | D16: =AFS!C136 -> 63.18 | E16: =AFS!D136 -> 69.61 | F16: =AFS!E136 -> 67.51 | G16: =AFS!F136 -> 75.42 | H16: =AFS!G136 -> 76.65 | I16: =AFS!H136 -> 115.51 | J16: =AFS!I136 -> 161.22 | ... L16: =AFS!K136 -> 148.79
B17: Net write-downs of fixed assets
B18: EBIT | C18: =C14-C16 -> 156.07 | D18: =D14-D16 -> 177.93 | E18: =E14-E16 -> 197.56 | F18: =F14-F16 -> 209.85 | G18: =G14-G16 -> 222.46 | H18: =H14-H16 -> 330.11 | I18: =I14-I16 -> 441.4 | J18: =J14-J16 -> 375.32 | ... L18: =L14-L16 -> 265.04
B19: Interest income | C19: =AFS!B48 -> -4.02 | D19: =AFS!C48 -> -2.38 | E19: =AFS!D48 -> -3.83 | F19: =AFS!E48 -> -1.14 | G19: =AFS!F48 -> -0.76 | H19: =AFS!G48 -> -1.91 | I19: =AFS!H48 -> 0.89 | J19: =AFS!I48 -> 1.37 | ... L19: =AFS!K48 -> 3.57
B20: Interest expenses | C20: =AFS!B45 -> -0.59 | D20: =AFS!C45 -> 1.38 | E20: =AFS!D45 -> 2.6 | F20: =AFS!E45 -> 2.49 | G20: =AFS!F45 -> 0.68 | H20: =AFS!G45 -> 0.94 | I20: =AFS!H45 -> 21.06 | J20: =AFS!I45 -> 30.72 | ... L20: =AFS!K45 -> 19.45
B21: Net Interest expenses | C21: =C19-C20 -> -3.43 | D21: =D19-D20 -> -3.76 | E21: =E19-E20 -> -6.43 | F21: =F19-F20 -> -3.63 | G21: =G19-G20 -> -1.44 | H21: =H19-H20 -> -2.85 | I21: =I19-I20 -> -20.17 | J21: =J19-J20 -> -29.35 | ... L21: =L19-L20 -> -15.88
B22: Gross Operating Income from Continuing Operations | C22: =C18+C21+AFS!B51 -> 152.21 | D22: =D18+D21+AFS!C51 -> 173.61 | E22: =E18+E21+AFS!D51 -> 190.73 | F22: =F18+F21+AFS!E51 -> 206.08 | G22: =G18+G21+AFS!F51 -> 220.91 | H22: =H18+H21+AFS!G51 -> 327.26 | I22: =I18+I21+AFS!H51 -> 421.23 | J22: =J18+J21+AFS!I51 -> 345.97 | ... L22: =L18+L21+AFS!K51 -> 249.16
B23: Non-Recurring | C23: =AFS!B54 -> -2.11 | D23: =AFS!C54 -> -5.43 | E23: =AFS!D54 -> -12.02 | F23: =AFS!E54 -> -1.71 | G23: =AFS!F54 -> -4.61 | H23: =AFS!G54 -> -5.88 | I23: =AFS!H54 -> -21.9 | J23: =AFS!I54 -> -20.02 | ... L23: =AFS!K54 -> -6.72
B24: EBT | C24: =C22+C23 -> 150.1 | D24: =D22+D23 -> 168.18 | E24: =E22+E23 -> 178.71 | F24: =F22+F23 -> 204.37 | G24: =G22+G23 -> 216.3 | H24: =H22+H23 -> 321.38 | I24: =I22+I23 -> 399.33 | J24: =J22+J23 -> 325.95 | ... L24: =L22+L23 -> 242.44
B25: Margin | C25: =C24/C8 -> 0.30069314 | D25: =D24/D8 -> 0.29541023 | E25: =E24/E8 -> 0.28033381 | F25: =F24/F8 -> 0.3053945 | G25: =G24/G8 -> 0.30623513 | H25: =H24/H8 -> 0.3646617 | I25: =I24/I8 -> 0.3226518 | J25: =J24/J8 -> 0.23946839 | ... L25: =L24/L8 -> 0.2045165
B26: Income taxes | C26: =-AFS!B64 -> -49.55 | D26: =-AFS!C64 -> -55.58 | E26: =-AFS!D64 -> -38.83 | F26: =-AFS!E64 -> -46.24 | G26: =-AFS!F64 -> -40.55 | H26: =-AFS!G64 -> -73.08 | I26: =-AFS!H64 -> -88.6 | J26: =-AFS!I64 -> -85.83 | ... L26: =-AFS!K64 -> -55.39
B27: Net Income | C27: =C24+C26 -> 100.55 | D27: =D24+D26 -> 112.6 | E27: =E24+E26 -> 139.88 | F27: =F24+F26 -> 158.13 | G27: =G24+G26 -> 175.75 | H27: =H24+H26 -> 248.3 | I27: =I24+I26 -> 310.73 | J27: =J24+J26 -> 240.12 | ... L27: =L24+L26 -> 187.05
B28: Minorities | C28: =AFS!B73 -> 0.13 | D28: =AFS!C73 -> 0.24 | E28: =AFS!D73 -> 0 | F28: =AFS!E73 -> 0 | G28: =AFS!F73 -> 0 | H28: =AFS!G73 -> 0.43 | I28: =AFS!H73 -> -0.24 | J28: =AFS!I73 -> -0.8 | ... L28: =AFS!K73 -> -1.05
B29: Group result of the year | C29: =C27-C28 -> 100.42 | D29: =D27-D28 -> 112.36 | E29: =E27-E28 -> 139.88 | F29: =F27-F28 -> 158.13 | G29: =G27-G28 -> 175.75 | H29: =H27-H28 -> 247.87 | I29: =I27-I28 -> 310.97 | J29: =J27-J28 -> 240.92 | ... L29: =L27-L28 -> 188.1
B30: Margin | C30: =C29/C8 -> 0.20116992 | D30: =D29/D8 -> 0.19736172 | E30: =E29/E8 -> 0.21942305 | F30: =F29/F8 -> 0.23629707 | G30: =G29/G8 -> 0.2488249 | H30: =H29/H8 -> 0.28125177 | I30: =I29/I8 -> 0.25125843 | J30: =J29/J8 -> 0.17699869 | ... L30: =L29/L8 -> 0.1586766
B31: Check
B32: Dividend distribution | C32: =AFS!B118+AFS!B120 -> 0.6 | D32: =AFS!C118+AFS!C120 -> 0.65 | E32: =AFS!D118+AFS!D120 -> 0.8 | F32: =AFS!E118+AFS!E120 -> 2.65 | G32: =AFS!F118+AFS!F120 -> 0.9 | H32: =AFS!G118+AFS!G120 -> 0.95 | I32: =AFS!H118+AFS!H120 -> 1 | J32: =AFS!I118+AFS!I120 -> 1.05 | ... L32: =AFS!K118+AFS!K120 -> 1.15
B33: Retained portion | C33: =C27-C28 -> 100.42 | D33: =D27-D28 -> 112.36 | E33: =E27-E28 -> 139.88 | F33: =F27-F28 -> 158.13 | G33: =G27-G28 -> 175.75 | H33: =H27-H28 -> 247.87 | I33: =I27-I28 -> 310.97 | J33: =J27-J28 -> 240.92 | ... L33: =L27-L28 -> 188.1
B36: Income statement
B38: Sales | C38: ='AFS3'!B3 -> 499.181 | D38: ='AFS3'!C3 -> 569.312 | E38: ='AFS3'!D3 -> 637.487 | F38: ='AFS3'!E3 -> 669.197 | G38: ='AFS3'!F3 -> 706.319 | H38: ='AFS3'!G3 -> 881.305 | I38: ='AFS3'!H3 -> 1237.654 | J38: ='AFS3'!I3 -> 1361.138 | ... L38: ='AFS3'!K3 -> 1185.427
B39: Growth | C39: n/a | D39: =D38/C38-1 -> 0.14049213 | E39: =E38/D38-1 -> 0.1197498 | F39: =F38/E38-1 -> 0.049742191 | G39: =G38/F38-1 -> 0.055472454 | H39: =H38/G38-1 -> 0.24774358 | I39: =I38/H38-1 -> 0.40434242 | J39: =J38/I38-1 -> 0.099772634 | K39: =K38/J38-1 -> -0.15643381 | L39: =L38/K38-1 -> 0.03241306
B41: (Cost of goods sold) | C41: =-'AFS3'!B5 -> -132.69 | D41: =-'AFS3'!C5 -> -154.022 | E41: =-'AFS3'!D5 -> -179.243 | F41: =-'AFS3'!E5 -> -189.581 | G41: =-'AFS3'!F5 -> -191.387 | H41: =-'AFS3'!G5 -> -240.119 | I41: =-'AFS3'!H5 -> -372.181 | J41: =-'AFS3'!I5 -> -415.288 | ... L41: =-'AFS3'!K5 -> -348.868
B42: (Selling, general & adminsitrative expenses) | C42: =-('AFS3'!B13+'AFS3'!B10) -> -177.142 | D42: =-('AFS3'!C13+'AFS3'!C10) -> -194.904 | E42: =-('AFS3'!D13+'AFS3'!D10) -> -214.205 | F42: =-('AFS3'!E13+'AFS3'!E10) -> -225.689 | G42: =-('AFS3'!F13+'AFS3'!F10) -> -235.833 | H42: =-('AFS3'!G13+'AFS3'!G10) -> -249.295 | I42: =-('AFS3'!H13+'AFS3'!H10) -> -337.534 | J42: =-('AFS3'!I13+'AFS3'!I10) -> -444.29 | ... L42: =-('AFS3'!K13+'AFS3'!K10) -> -429.866
B43: EBITDA | C43: =SUM(C38,C41,C42) -> 189.349 | D43: =SUM(D38,D41,D42) -> 220.386 | E43: =SUM(E38,E41,E42) -> 244.039 | F43: =SUM(F38,F41,F42) -> 253.927 | G43: =SUM(G38,G41,G42) -> 279.099 | H43: =SUM(H38,H41,H42) -> 391.891 | I43: =SUM(I38,I41,I42) -> 527.939 | J43: =SUM(J38,J41,J42) -> 501.56 | ... L43: =SUM(L38,L41,L42) -> 406.693
B44: Margin | C44: =C43/C38 -> 0.37931933 | D44: =D43/D38 -> 0.38710935 | E44: =E43/E38 -> 0.38281408 | F44: =F43/F38 -> 0.3794503 | G44: =G43/G38 -> 0.39514582 | H44: =H43/H38 -> 0.44467125 | I44: =I43/I38 -> 0.42656429 | J44: =J43/J38 -> 0.36848578 | ... L44: =L43/L38 -> 0.34307722
B46: (Depreciation) | C46: =-'AFS3'!B7 -> -24.875 | D46: =-'AFS3'!C7 -> -27.141 | E46: =-'AFS3'!D7 -> -29.666 | F46: =-'AFS3'!E7 -> -28.531 | G46: =-'AFS3'!F7 -> -35.132 | H46: =-'AFS3'!G7 -> -33.558 | I46: =-'AFS3'!H7 -> -47.131 | J46: =-'AFS3'!I7 -> -60.404 | ... L46: =-'AFS3'!K7 -> -53.871
B47: (Amortization) | C47: =-'AFS3'!B8 -> -8.109 | D47: =-'AFS3'!C8 -> -17.566 | E47: =-'AFS3'!D8 -> -16.185 | F47: =-'AFS3'!E8 -> -16.844 | G47: =-'AFS3'!F8 -> -17.644 | H47: =-'AFS3'!G8 -> -25.255 | I47: =-'AFS3'!H8 -> -36.275 | J47: =-'AFS3'!I8 -> -58.94 | ... L47: =-'AFS3'!K8 -> -75.17
B48: EBIT | C48: =SUM(C43,C46,C47) -> 156.365 | D48: =SUM(D43,D46,D47) -> 175.679 | E48: =SUM(E43,E46,E47) -> 198.188 | F48: =SUM(F43,F46,F47) -> 208.552 | G48: =SUM(G43,G46,G47) -> 226.323 | H48: =SUM(H43,H46,H47) -> 333.078 | I48: =SUM(I43,I46,I47) -> 444.533 | J48: =SUM(J43,J46,J47) -> 382.216 | ... L48: =SUM(L43,L46,L47) -> 277.652
...

Sheet Assumptions
B2: Assumptions
F3: Historicals | P3: Explicit forecast
B5: (EUR m) | F5: 2015 | G5: =F5+1 -> 2016 | H5: =G5+1 -> 2017 | I5: =H5+1 -> 2018 | J5: =I5+1 -> 2019 | K5: =J5+1 -> 2020 | L5: =K5+1 -> 2021 | M5: =L5+1 -> 2022 | N5: =M5+1 -> 2023 | ... T5: =S5+1 -> 2029 | V5: Notes
B8: Sales forecast assumptions
B10: Sales growth rates
B11: PAST | G11: =Restatements!D8/Restatements!C8-1 -> 0.1404904 | H11: =Restatements!E8/Restatements!D8-1 -> 0.11975901 | I11: =Restatements!F8/Restatements!E8-1 -> 0.049741957 | J11: =Restatements!G8/Restatements!F8-1 -> 0.055469217 | K11: =Restatements!H8/Restatements!G8-1 -> 0.2477489 | L11: =Restatements!I8/Restatements!H8-1 -> 0.40432992 | M11: =Restatements!J8/Restatements!I8-1 -> 0.099777805 | N11: =Restatements!K8/Restatements!J8-1 -> -0.15643505 | O11: =Restatements!L8/Restatements!K8-1 -> 0.032415673 | P11: =+AVERAGE($G$11:$J$11,$O$11) -> 0.079575252 | Q11: =+AVERAGE($G$11:$J$11,$O$11) -> 0.079575252 | R11: =+AVERAGE($G$11:$J$11,$O$11) -> 0.079575252 | S11: =+AVERAGE($G$11:$J$11,$O$11) -> 0.079575252 | T11: =+AVERAGE($G$11:$J$11,$O$11) -> 0.079575252
B12: BASE CASE | P12: 0.05 | Q12: 0.05 | R12: 0.05 | S12: 0.05 | T12: 0.05
B14: Operating expenses forecast assumptions
B16: COGS as a % of sales | F16: =-Restatements!C41/Restatements!C8 -> 0.26581594 | G16: =-Restatements!D41/Restatements!D8 -> 0.27054153 | H16: =-Restatements!E41/Restatements!E8 -> 0.2811699 | I16: =-Restatements!F41/Restatements!F8 -> 0.28329498 | J16: =-Restatements!G41/Restatements!G8 -> 0.27096359 | K16: =-Restatements!H41/Restatements!H8 -> 0.27245691 | L16: =-Restatements!I41/Restatements!I8 -> 0.30071587 | M16: =-Restatements!J41/Restatements!J8 -> 0.30510308 | ... O16: =-Restatements!L41/Restatements!L8 -> 0.29429658 | P16: 0.30430467 | Q16: 0.30430467 | R16: 0.3 | S16: 0.3 | T16: 0.3
B17: SG&A as a % of sales | F17: =-Restatements!C42/Restatements!C8 -> 0.35486598 | G17: =-Restatements!D42/Restatements!D8 -> 0.34235127 | H17: =-Restatements!E42/Restatements!E8 -> 0.33601311 | I17: =-Restatements!F42/Restatements!F8 -> 0.33725194 | J17: =-Restatements!G42/Restatements!G8 -> 0.33388974 | K17: =-Restatements!H42/Restatements!H8 -> 0.28286868 | L17: =-Restatements!I42/Restatements!I8 -> 0.27272169 | M17: =-Restatements!J42/Restatements!J8 -> 0.32641021 | ... O17: =-Restatements!L42/Restatements!L8 -> 0.36262453 | P17: =O17*(1+$O$17-$T$17)^(1/5) -> 0.3647738 | Q17: 0.36 | R17: 0.33 | S17: 0.33 | T17: =+AVERAGE($F17:$O17) -> 0.33263628 | W17: Equity | Y17: EV
V18: EV/EBITDA LTM | W18: 5398.5226 | X18: 643.35306 | Y18: 6041.8757
B19: Investment forecast assumptions | V19: P/E LTM | W19: 5976.9649 | X19: 643.35306 | Y19: 6620.318
B21: Tangible CAPEX as a % of sales | F21: =-Restatements!C120/Restatements!C38 -> 0 | G21: =-Restatements!D120/Restatements!D38 -> 0.078659856 | H21: =-Restatements!E120/Restatements!E38 -> 0.046846445 | I21: =-Restatements!F120/Restatements!F38 -> 0.046593156 | J21: =-Restatements!G120/Restatements!G38 -> 0.097032644 | K21: =-Restatements!H120/Restatements!H38 -> 0.051820879 | L21: =-Restatements!I120/Restatements!I38 -> 0.14772384 | M21: =-Restatements!J120/Restatements!J38 -> 0.038684542 | ... O21: =-Restatements!L120/Restatements!L38 -> 0.058159634 | P21: =+AVERAGE($H21:$I21) -> 0.046719801 | Q21: =+AVERAGE($H21:$I21) -> 0.046719801 | R21: =+AVERAGE($H21:$I21) -> 0.046719801 | S21: =+AVERAGE($H21:$I21) -> 0.046719801 | T21: =+AVERAGE($H21:$I21) -> 0.046719801
B22: Depreciation rate | G22: =-Restatements!D46/Restatements!C79 -> 0.36434296 | H22: =-Restatements!E46/Restatements!D79 -> 0.32198754 | I22: =-Restatements!F46/Restatements!E79 -> 0.30900446 | J22: =-Restatements!G46/Restatements!F79 -> 0.3698845 | K22: =-Restatements!H46/Restatements!G79 -> 0.26138568 | L22: =-Restatements!I46/Restatements!H79 -> 0.33545912 | M22: =-Restatements!J46/Restatements!I79 -> 0.21869897 | N22: =-Restatements!K46/Restatements!J79 -> 0.23032021 | O22: =-Restatements!L46/Restatements!K79 -> 0.21019876 | P22: =+AVERAGE($N22:$O22) -> 0.22025949 | Q22: =+AVERAGE($M22:$O22) -> 0.21973932 | R22: =+AVERAGE($M22:$O22) -> 0.21973932 | S22: =+AVERAGE($M22:$O22) -> 0.21973932 | T22: =+AVERAGE($M22:$O22) -> 0.21973932
B24: Intangible CAPEX as a % of sales | G24: =-Restatements!D121/Restatements!D38 -> 0.45097591 | H24: =-Restatements!E121/Restatements!E38 -> 0.0054103064 | I24: =-Restatements!F121/Restatements!F38 -> 0.068108494 | J24: =-Restatements!G121/Restatements!G38 -> 0.021008921 | K24: =-Restatements!H121/Restatements!H38 -> 0.013290518 | L24: =-Restatements!I121/Restatements!I38 -> 1.3112768 | M24: =-Restatements!J121/Restatements!J38 -> 0.081280517 | N24: =-Restatements!K121/Restatements!K38 -> -0.014715078 | O24: =-Restatements!L121/Restatements!L38 -> 0.15073556 | P24: =AVERAGE($H$24:$K$24,$M$24:$O$24) -> 0.046445605 | Q24: =AVERAGE($H$24:$K$24,$M$24:$O$24) -> 0.046445605 | R24: =AVERAGE($H$24:$K$24,$M$24:$O$24) -> 0.046445605 | S24: =AVERAGE($H$24:$K$24,$M$24:$O$24) -> 0.046445605 | T24: =AVERAGE($H$24:$K$24,$M$24:$O$24) -> 0.046445605
B25: Intangibles amortization as a % of BOP Intangibles | G25: =-Restatements!D121/SUM(Restatements!C80:C81) -> 2.1775482 | H25: =-Restatements!E121/SUM(Restatements!D80:D81) -> 0.0096587377 | I25: =-Restatements!F121/SUM(Restatements!E80:E81) -> 0.13235952 | J25: =-Restatements!G121/SUM(Restatements!F80:F81) -> 0.039773885 | K25: =-Restatements!H121/SUM(Restatements!G80:G81) -> 0.031632904 | L25: =-Restatements!I121/SUM(Restatements!H80:H81) -> 4.5493094 | M25: =-Restatements!J121/SUM(Restatements!I80:I81) -> 0.056928972 | N25: =-Restatements!K121/SUM(Restatements!J80:J81) -> -0.0084689055 | O25: =-Restatements!L121/SUM(Restatements!K80:K81) -> 0.092825343 | P25: =AVERAGE($O$25,$N$25,$M$25,$K$25,$J$25,$H$25) -> 0.037058489 | Q25: =AVERAGE($O$25,$N$25,$M$25,$K$25,$J$25,$H$25) -> 0.037058489 | R25: =AVERAGE($O$25,$N$25,$M$25,$K$25,$J$25,$H$25) -> 0.037058489 | S25: =AVERAGE($O$25,$N$25,$M$25,$K$25,$J$25,$H$25) -> 0.037058489 | T25: =AVERAGE($O$25,$N$25,$M$25,$K$25,$J$25,$H$25) -> 0.037058489
B27: Days receivables (Sales) | F27: =+(Restatements!C70*365)/(Restatements!C38*(1+$F$46)) -> 63.295949 | G27: =+(Restatements!D70*365)/(Restatements!D38*(1+$F$46)) -> 63.198607 | H27: =+(Restatements!E70*365)/(Restatements!E38*(1+$F$46)) -> 69.101506 | I27: =+(Restatements!F70*365)/(Restatements!F38*(1+$F$46)) -> 60.911099 | J27: =+(Restatements!G70*365)/(Restatements!G38*(1+$F$46)) -> 59.512538 | K27: =+(Restatements!H70*365)/(Restatements!H38*(1+$F$46)) -> 56.585939 | L27: =+(Restatements!I70*365)/(Restatements!I38*(1+$F$46)) -> 54.691578 | M27: =+(Restatements!J70*365)/(Restatements!J38*(1+$F$46)) -> 53.049779 | ... O27: =+(Restatements!L70*365)/(Restatements!L38*(1+$F$46)) -> 51.513924 | P27: =+AVERAGE($M27:$O27) -> 54.719061 | Q27: =+AVERAGE($M27:$O27) -> 54.719061 | R27: =+AVERAGE($M27:$O27) -> 54.719061 | S27: =+AVERAGE($M27:$O27) -> 54.719061 | T27: =+AVERAGE($M27:$O27) -> 54.719061
B28: Days payables (COGS) | F28: =Restatements!C71*365/(Restatements!C41*(1+$F$46)) -> 91.936678 | G28: =Restatements!D71*365/(Restatements!D41*(1+$F$46)) -> 92.604452 | H28: =Restatements!E71*365/(Restatements!E41*(1+$F$46)) -> 104.0387 | I28: =Restatements!F71*365/(Restatements!F41*(1+$F$46)) -> 90.403808 | J28: =Restatements!G71*365/(Restatements!G41*(1+$F$46)) -> 87.12304 | K28: =Restatements!H71*365/(Restatements!H41*(1+$F$46)) -> 81.592143 | L28: =Restatements!I71*365/(Restatements!I41*(1+$F$46)) -> 68.145375 | M28: =Restatements!J71*365/(Restatements!J41*(1+$F$46)) -> 75.070281 | ... O28: =Restatements!L71*365/(Restatements!L41*(1+$F$46)) -> 85.345822 | P28: =+AVERAGE($F$28:$I$28,$O$28) -> 92.865892 | Q28: =+AVERAGE($F$28:$I$28,$O$28) -> 92.865892 | R28: =+AVERAGE($F$28:$I$28,$O$28) -> 92.865892 | S28: =+AVERAGE($F$28:$I$28,$O$28) -> 92.865892 | T28: =+AVERAGE($F$28:$I$28,$O$28) -> 92.865892
B29: Days inventory (Sales) | F29: =365*Restatements!C72/Restatements!C8 -> 77.648233 | G29: =365*Restatements!D72/Restatements!D8 -> 82.622034 | H29: =365*Restatements!E72/Restatements!E8 -> 81.762428 | I29: =365*Restatements!F72/Restatements!F8 -> 87.484369 | J29: =365*Restatements!G72/Restatements!G8 -> 88.432092 | K29: =365*Restatements!H72/Restatements!H8 -> 79.200747 | L29: =365*Restatements!I72/Restatements!I8 -> 87.898748 | M29: =365*Restatements!J72/Restatements!J8 -> 82.191101 | ... O29: =365*Restatements!L72/Restatements!L8 -> 105.93261 | P29: =+AVERAGE($F29:$H29) -> 80.677565 | Q29: =+AVERAGE($F29:$H29) -> 80.677565 | R29: =+AVERAGE($F29:$H29) -> 80.677565 | S29: =+AVERAGE($F29:$H29) -> 80.677565 | T29: =+AVERAGE($F29:$H29) -> 80.677565
B31: Other current assets / liabilities as a % of sales | F31: =Restatements!C73/Restatements!C38 -> -0.041684279 | G31: =Restatements!D73/Restatements!D38 -> -0.055484515 | H31: =Restatements!E73/Restatements!E38 -> -0.049889645 | I31: =Restatements!F73/Restatements!F38 -> -0.043868995 | J31: =Restatements!G73/Restatements!G38 -> -0.048335101 | K31: =Restatements!H73/Restatements!H38 -> -0.050719104 | L31: =Restatements!I73/Restatements!I38 -> -0.061258639 | M31: =Restatements!J73/Restatements!J38 -> -0.026035567 | ... O31: =Restatements!L73/Restatements!L38 -> -0.07100142 | P31: =AVERAGE($F$31:$O$31) -> -0.050512314 | Q31: =AVERAGE($F$31:$O$31) -> -0.050512314 | R31: =AVERAGE($F$31:$O$31) -> -0.050512314 | S31: =AVERAGE($F$31:$O$31) -> -0.050512314 | T31: =AVERAGE($F$31:$O$31) -> -0.050512314
B33: Financing forecast assumptions
B35: Payout ratio | F35: =Restatements!C65/Restatements!C62 -> 0.0064728142 | G35: =Restatements!D65/Restatements!D62 -> 0.0071185144 | H35: =Restatements!E65/Restatements!E62 -> 0.006076724 | I35: =Restatements!F65/Restatements!F62 -> 0.0056915916 | J35: =Restatements!G65/Restatements!G62 -> 0.0054058668 | K35: =Restatements!H65/Restatements!H62 -> 0.0040343566 | L35: =Restatements!I65/Restatements!I62 -> 0.0033765532 | M35: =Restatements!J65/Restatements!J62 -> 0.0045660774 | ... O35: =Restatements!L65/Restatements!L62 -> 0.0063794158 | P35: =+AVERAGE($F35:$O35) -> 0.0056316203 | Q35: =+AVERAGE($F35:$O35) -> 0.0056316203 | R35: =+AVERAGE($F35:$O35) -> 0.0056316203 | S35: =+AVERAGE($F35:$O35) -> 0.0056316203 | T35: =+AVERAGE($F35:$O35) -> 0.0056316203
B36: Rights issues (issue of common stock)
B38: ST debt as a % of sales | F38: =Restatements!C93/Restatements!C38 -> 0.0046075472 | G38: =Restatements!D93/Restatements!D38 -> 0.04656849 | H38: =Restatements!E93/Restatements!E38 -> 0.037506647 | I38: =Restatements!F93/Restatements!F38 -> 0.030784657 | J38: =Restatements!G93/Restatements!G38 -> 0.0068127857 | K38: =Restatements!H93/Restatements!H38 -> 0.0047758721 | L38: =Restatements!I93/Restatements!I38 -> 0.081130106 | M38: =Restatements!J93/Restatements!J38 -> 0.088176217 | ... O38: =Restatements!L93/Restatements!L38 -> 0.040309526 | P38: =+AVERAGE($I$38,$G$38,$F$38) -> 0.027320231 | Q38: =+AVERAGE($I$38,$G$38,$F$38) -> 0.027320231 | R38: =+AVERAGE($I$38,$G$38,$F$38) -> 0.027320231 | S38: =+AVERAGE($I$38,$G$38,$F$38) -> 0.027320231 | T38: =+AVERAGE($I$38,$G$38,$F$38) -> 0.027320231
B39: Effective interest rate for debt | G39: =-SUM(Restatements!D53)/AVERAGE(Restatements!C95:D95) -> 0.11783681 | H39: =-SUM(Restatements!E53)/AVERAGE(Restatements!D95:E95) -> 0.11108423 | I39: =-SUM(Restatements!F53)/AVERAGE(Restatements!E95:F95) -> 0.19322504 | J39: =-SUM(Restatements!G53)/AVERAGE(Restatements!F95:G95) -> 0.15868695 | K39: =-SUM(Restatements!H53)/AVERAGE(Restatements!G95:H95) -> 0.10726016 | L39: =-SUM(Restatements!I53)/AVERAGE(Restatements!H95:I95) -> 0.030512974 | M39: =-SUM(Restatements!J53)/AVERAGE(Restatements!I95:J95) -> 0.025063857 | N39: =-SUM(Restatements!K53)/AVERAGE(Restatements!J95:K95) -> 0.023082253 | O39: =-SUM(Restatements!L53)/AVERAGE(Restatements!K95:L95) -> 0.025045091 | P39: =+AVERAGE($J39:$O39) -> 0.061608547 | Q39: =+AVERAGE($J39:$O39) -> 0.061608547 | R39: =+AVERAGE($J39:$O39) -> 0.061608547 | S39: =+AVERAGE($J39:$O39) -> 0.061608547 | T39: =+AVERAGE($J39:$O39) -> 0.061608547
B40: Bonds issuance schedule
B41: Bonds maturity schedule
B42: Effective interest rate for cash / overdraft | G42: =Restatements!D52/AVERAGE(Restatements!C96:D96) -> 0.005343978 | H42: =Restatements!E52/AVERAGE(Restatements!D96:E96) -> 0.0080518266 | I42: =Restatements!F52/AVERAGE(Restatements!E96:F96) -> 0.011228918 | J42: =Restatements!G52/AVERAGE(Restatements!F96:G96) -> 0.018971088 | K42: =Restatements!H52/AVERAGE(Restatements!G96:H96) -> 0.0073965179 | L42: =Restatements!I52/AVERAGE(Restatements!H96:I96) -> 0.00076444059 | M42: =Restatements!J52/AVERAGE(Restatements!I96:J96) -> 0.01374109 | N42: =Restatements!K52/AVERAGE(Restatements!J96:K96) -> 0.034119227 | O42: =Restatements!L52/AVERAGE(Restatements!K96:L96) -> 0.032445582 | P42: =AVERAGE($G$42:$O$42) -> 0.01467363 | Q42: =AVERAGE($G$42:$O$42) -> 0.01467363 | R42: =AVERAGE($G$42:$O$42) -> 0.01467363 | S42: =AVERAGE($G$42:$O$42) -> 0.01467363 | T42: =AVERAGE($G$42:$O$42) -> 0.01467363
B44: Tax forecast assumptions
B46: Value added tax (sales tax) | F46: 0.22 | G46: =+$F46 -> 0.22 | H46: =+$F46 -> 0.22 | I46: =+$F46 -> 0.22 | J46: =+$F46 -> 0.22 | K46: =+$F46 -> 0.22 | L46: =+$F46 -> 0.22 | M46: =+$F46 -> 0.22 | N46: =+$F46 -> 0.22 | ... T46: =+$F46 -> 0.22
B47: Income tax 1 on EBT (IRES) | F47: 0.24 | G47: =+$F47 -> 0.24 | H47: =+$F47 -> 0.24 | I47: =+$F47 -> 0.24 | J47: =+$F47 -> 0.24 | K47: =+$F47 -> 0.24 | L47: =+$F47 -> 0.24 | M47: =+$F47 -> 0.24 | N47: =+$F47 -> 0.24 | ... T47: =+$F47 -> 0.24
B48: Income tax 2 on EBIT (IRAP) | F48: 0.039 | G48: =+$F48 -> 0.039 | H48: =+$F48 -> 0.039 | I48: =+$F48 -> 0.039 | J48: =+$F48 -> 0.039 | K48: =+$F48 -> 0.039 | L48: =+$F48 -> 0.039 | M48: =+$F48 -> 0.039 | N48: =+$F48 -> 0.039 | ... T48: =+$F48 -> 0.039
B50: Steady state assumptions
B52: Terminal growth rate (2022 onwards) | T52: 0.02

Sheet Calculations >>>
C12: DIASORIN
C13: Financial Model
C17: Calculations

Sheet SalesOPEX
B2: Sales and Operating Expenses Forecasts
F3: Historicals | P3: Explicit forecast
B5: =[1]AsReported!B5 -> (EUR m) | F5: 2015 | G5: =F5+1 -> 2016 | H5: =G5+1 -> 2017 | I5: =H5+1 -> 2018 | J5: =I5+1 -> 2019 | K5: =J5+1 -> 2020 | L5: =K5+1 -> 2021 | M5: =L5+1 -> 2022 | N5: =M5+1 -> 2023 | ... T5: =S5+1 -> 2029 | V5: Notes
B8: Sales forecast
B10: Base Case | F10: =Restatements!C8 -> 499.18 | G10: =Restatements!D8 -> 569.31 | H10: =Restatements!E8 -> 637.49 | I10: =Restatements!F8 -> 669.2 | J10: =Restatements!G8 -> 706.32 | K10: =Restatements!H8 -> 881.31 | L10: =Restatements!I8 -> 1237.65 | M10: =Restatements!J8 -> 1361.14 | ... O10: =Restatements!L8 -> 1185.43 | P10: 1200 | Q10: =P10*(1+Assumptions!Q12) -> 1260 | R10: =Q10*(1+Assumptions!R12) -> 1323 | S10: =R10*(1+Assumptions!S12) -> 1389.15 | T10: =S10*(1+Assumptions!T12) -> 1458.6075
B11: Best Case | P11: =O10*(1+Assumptions!P11) -> 1279.7609 | Q11: =P10*(1+Assumptions!Q11) -> 1295.4903 | R11: =Q10*(1+Assumptions!R11) -> 1360.2648 | S11: =R10*(1+Assumptions!S11) -> 1428.2781 | T11: =S10*(1+Assumptions!T11) -> 1499.692
B13: Operational forecasts
B15: COGS | F15: =-Restatements!C10 -> -157.28 | G15: =-Restatements!D10 -> -180.16 | H15: =-Restatements!E10 -> -205.59 | I15: =-Restatements!F10 -> -213.43 | J15: =-Restatements!G10 -> -217.63 | K15: =-Restatements!H10 -> -278.4 | L15: =-Restatements!I10 -> -412.88 | M15: =-Restatements!J10 -> -460.53 | ... O15: =-Restatements!L10 -> -403.73 | P15: =-P$10*Assumptions!P16 -> -365.1656 | Q15: =-Q$10*Assumptions!Q16 -> -383.42388 | R15: =-R$10*Assumptions!R16 -> -396.9 | S15: =-S$10*Assumptions!S16 -> -416.745 | T15: =-T$10*Assumptions!T16 -> -437.58225
B16: SGAs | F16: =-Restatements!C11 -> -132.91 | G16: =-Restatements!D11 -> -148.79 | H16: =-Restatements!E11 -> -163.4 | I16: =-Restatements!F11 -> -179.71 | J16: =-Restatements!G11 -> -186.95 | K16: =-Restatements!H11 -> -193.18 | L16: =-Restatements!I11 -> -264.73 | M16: =-Restatements!J11 -> -357.18 | ... O16: =-Restatements!L11 -> -361.65 | P16: =-P$10*Assumptions!P17 -> -437.72856 | Q16: =-Q$10*Assumptions!Q17 -> -453.6 | R16: =-R$10*Assumptions!R17 -> -436.59 | S16: =-S$10*Assumptions!S17 -> -458.4195 | T16: =-T$10*Assumptions!T17 -> -485.18577
P17: =(P16+P15)/P10 -> -0.66907847

Sheet Investments
B2: Investments Forecasts
F3: Historicals | P3: Explicit forecast
B5: =[1]AsReported!B5 -> (EUR m) | F5: 42192 | G5: =F5+365 -> 42557 | H5: =G5+365 -> 42922 | I5: =H5+365 -> 43287 | J5: =I5+365 -> 43652 | K5: =J5+365 -> 44017 | L5: =K5+365 -> 44382 | M5: =L5+365 -> 44747 | N5: =M5+365 -> 45112 | ... T5: =S5+365 -> 47302 | V5: Notes
B8: Working capital forecast
B10: Trade receivables | P10: =+(Assumptions!P27*SalesOPEX!P10*(1+Assumptions!P$46))/365 -> 219.47591 | Q10: =+(Assumptions!Q27*SalesOPEX!Q10*(1+Assumptions!Q$46))/365 -> 230.4497 | R10: =+(Assumptions!R27*SalesOPEX!R10*(1+Assumptions!R$46))/365 -> 241.97219 | S10: =+(Assumptions!S27*SalesOPEX!S10*(1+Assumptions!S$46))/365 -> 254.0708 | T10: =+(Assumptions!T27*SalesOPEX!T10*(1+Assumptions!T$46))/365 -> 266.77434
B11: Trade payables | P11: =+(Assumptions!P28*SalesOPEX!P15*(1+Assumptions!P$46))/365 -> -113.34779 | Q11: =+(Assumptions!Q28*SalesOPEX!Q15*(1+Assumptions!Q$46))/365 -> -119.01518 | R11: =+(Assumptions!R28*SalesOPEX!R15*(1+Assumptions!R$46))/365 -> -123.19818 | S11: =+(Assumptions!S28*SalesOPEX!S15*(1+Assumptions!S$46))/365 -> -129.35809 | T11: =+(Assumptions!T28*SalesOPEX!T15*(1+Assumptions!T$46))/365 -> -135.826
B12: Inventory | P12: =+(Assumptions!P29*SalesOPEX!P10)/365 -> 265.24131 | Q12: =+(Assumptions!Q29*SalesOPEX!Q10)/365 -> 278.50337 | R12: =+(Assumptions!R29*SalesOPEX!R10)/365 -> 292.42854 | S12: =+(Assumptions!S29*SalesOPEX!S10)/365 -> 307.04997 | T12: =+(Assumptions!T29*SalesOPEX!T10)/365 -> 322.40247
B13: Other current assets & liabilities | P13: =Assumptions!P$31*SalesOPEX!P10 -> -60.614777 | Q13: =Assumptions!Q$31*SalesOPEX!Q10 -> -63.645515 | R13: =Assumptions!R$31*SalesOPEX!R10 -> -66.827791 | S13: =Assumptions!S$31*SalesOPEX!S10 -> -70.169181 | T13: =Assumptions!T$31*SalesOPEX!T10 -> -73.67764
B15: Deferred taxes | O15: =Restatements!L74 -> -167.969 | P15: =O15 -> -167.969 | Q15: =+P15 -> -167.969 | R15: =+Q15 -> -167.969 | S15: =+R15 -> -167.969 | T15: =+S15 -> -167.969
B16: Long term provisions | O16: =Restatements!L76 -> -54.663 | P16: =O16 -> -54.663 | Q16: =+P16 -> -54.663 | R16: =+Q16 -> -54.663 | S16: =+R16 -> -54.663 | T16: =+S16 -> -54.663
B18: Investment forecasts
B20: Evolution of tangible assets
B21: BOP tangible assets | P21: =+O24 -> 271.359 | Q21: =+P24 -> 297.53806 | R21: =+Q24 -> 290.61707 | S21: =+R24 -> 274.01202 | T21: =+S24 -> 247.23872
B22: + Tangible CAPEX | P22: =SalesOPEX!P10*Assumptions!P21 -> 56.063761 | Q22: =SalesOPEX!Q10*Assumptions!Q21 -> 58.866949 | R22: =SalesOPEX!R10*Assumptions!R21 -> 61.810296 | S22: =SalesOPEX!S10*Assumptions!S21 -> 64.900811 | T22: =SalesOPEX!T10*Assumptions!T21 -> 68.145852
B23: - Depreciation | O23: =Restatements!L46 -> -53.871 | P23: =+P32 -> -29.884697 | Q23: =+Q32 -> -65.787947 | R23: =+R32 -> -78.415345 | S23: =+S32 -> -91.674112 | T23: =+T32 -> -105.59582
B24: = EOP tangible assets | O24: =Restatements!L79 -> 271.359 | P24: =+SUM(P21:P23) -> 297.53806 | Q24: =+SUM(Q21:Q23) -> 290.61707 | R24: =+SUM(R21:R23) -> 274.01202 | S24: =+SUM(S21:S23) -> 247.23872 | T24: =+SUM(T21:T23) -> 209.78875
B26: Existing assets | C26: =+P5 -> 45842 | D26: =+O24 -> 271.359 | P26: =-MIN($D26+SUM($I26:I26),$D26*Assumptions!P$22)*(P$5>=$C26)*(IF(P$5=$C26,0.5,1)) -> -29.884697 | Q26: =-MIN($D26+SUM($I26:P26),$D26*Assumptions!Q$22)*(Q$5>=$C26)*(IF(Q$5=$C26,0.5,1)) -> -59.628241 | R26: =-MIN($D26+SUM($I26:Q26),$D26*Assumptions!R$22)*(R$5>=$C26)*(IF(R$5=$C26,0.5,1)) -> -59.628241 | S26: =-MIN($D26+SUM($I26:R26),$D26*Assumptions!S$22)*(S$5>=$C26)*(IF(S$5=$C26,0.5,1)) -> -59.628241 | T26: =-MIN($D26+SUM($I26:S26),$D26*Assumptions!T$22)*(T$5>=$C26)*(IF(T$5=$C26,0.5,1)) -> -59.628241
B27: ="CAPEX Year "&YEAR(P5) -> CAPEX Year 2025 | C27: =C26+365 -> 46207 | D27: =P22 -> 56.063761 | P27: =-MIN($D27+SUM($I27:I27),$D27*Assumptions!P$22)*(P$5>=$C27)*(IF(P$5=$C27,0.5,1)) -> 0 | Q27: =-MIN($D27+SUM($I27:P27),$D27*Assumptions!Q$22)*(Q$5>=$C27)*(IF(Q$5=$C27,0.5,1)) -> -6.1597062 | R27: =-MIN($D27+SUM($I27:Q27),$D27*Assumptions!R$22)*(R$5>=$C27)*(IF(R$5=$C27,0.5,1)) -> -12.319412 | S27: =-MIN($D27+SUM($I27:R27),$D27*Assumptions!S$22)*(S$5>=$C27)*(IF(S$5=$C27,0.5,1)) -> -12.319412 | T27: =-MIN($D27+SUM($I27:S27),$D27*Assumptions!T$22)*(T$5>=$C27)*(IF(T$5=$C27,0.5,1)) -> -12.319412
B28: ="CAPEX Year "&YEAR(Q5) -> CAPEX Year 2026 | C28: =C27+365 -> 46572 | D28: =Q22 -> 58.866949 | P28: =-MIN($D28+SUM($I28:I28),$D28*Assumptions!P$22)*(P$5>=$C28)*(IF(P$5=$C28,0.5,1)) -> 0 | Q28: =-MIN($D28+SUM($I28:P28),$D28*Assumptions!Q$22)*(Q$5>=$C28)*(IF(Q$5=$C28,0.5,1)) -> 0 | R28: =-MIN($D28+SUM($I28:Q28),$D28*Assumptions!R$22)*(R$5>=$C28)*(IF(R$5=$C28,0.5,1)) -> -6.4676915 | S28: =-MIN($D28+SUM($I28:R28),$D28*Assumptions!S$22)*(S$5>=$C28)*(IF(S$5=$C28,0.5,1)) -> -12.935383 | T28: =-MIN($D28+SUM($I28:S28),$D28*Assumptions!T$22)*(T$5>=$C28)*(IF(T$5=$C28,0.5,1)) -> -12.935383
B29: ="CAPEX Year "&YEAR(R5) -> CAPEX Year 2027 | C29: =C28+365 -> 46937 | D29: =R22 -> 61.810296 | P29: =-MIN($D29+SUM($I29:I29),$D29*Assumptions!P$22)*(P$5>=$C29)*(IF(P$5=$C29,0.5,1)) -> 0 | Q29: =-MIN($D29+SUM($I29:P29),$D29*Assumptions!Q$22)*(Q$5>=$C29)*(IF(Q$5=$C29,0.5,1)) -> 0 | R29: =-MIN($D29+SUM($I29:Q29),$D29*Assumptions!R$22)*(R$5>=$C29)*(IF(R$5=$C29,0.5,1)) -> 0 | S29: =-MIN($D29+SUM($I29:R29),$D29*Assumptions!S$22)*(S$5>=$C29)*(IF(S$5=$C29,0.5,1)) -> -6.7910761 | T29: =-MIN($D29+SUM($I29:S29),$D29*Assumptions!T$22)*(T$5>=$C29)*(IF(T$5=$C29,0.5,1)) -> -13.582152
B30: ="CAPEX Year "&YEAR(S5) -> CAPEX Year 2028 | C30: =C29+365 -> 47302 | D30: =S22 -> 64.900811 | P30: =-MIN($D30+SUM($I30:I30),$D30*Assumptions!P$22)*(P$5>=$C30)*(IF(P$5=$C30,0.5,1)) -> 0 | Q30: =-MIN($D30+SUM($I30:P30),$D30*Assumptions!Q$22)*(Q$5>=$C30)*(IF(Q$5=$C30,0.5,1)) -> 0 | R30: =-MIN($D30+SUM($I30:Q30),$D30*Assumptions!R$22)*(R$5>=$C30)*(IF(R$5=$C30,0.5,1)) -> 0 | S30: =-MIN($D30+SUM($I30:R30),$D30*Assumptions!S$22)*(S$5>=$C30)*(IF(S$5=$C30,0.5,1)) -> 0 | T30: =-MIN($D30+SUM($I30:S30),$D30*Assumptions!T$22)*(T$5>=$C30)*(IF(T$5=$C30,0.5,1)) -> -7.1306299
B31: ="CAPEX Year "&YEAR(T5) -> CAPEX Year 2029 | C31: =C30+365 -> 47667 | D31: =T22 -> 68.145852 | P31: =-MIN($D31+SUM($I31:I31),$D31*Assumptions!P$22)*(P$5>=$C31)*(IF(P$5=$C31,0.5,1)) -> 0 | Q31: =-MIN($D31+SUM($I31:P31),$D31*Assumptions!Q$22)*(Q$5>=$C31)*(IF(Q$5=$C31,0.5,1)) -> 0 | R31: =-MIN($D31+SUM($I31:Q31),$D31*Assumptions!R$22)*(R$5>=$C31)*(IF(R$5=$C31,0.5,1)) -> 0 | S31: =-MIN($D31+SUM($I31:R31),$D31*Assumptions!S$22)*(S$5>=$C31)*(IF(S$5=$C31,0.5,1)) -> 0 | T31: =-MIN($D31+SUM($I31:S31),$D31*Assumptions!T$22)*(T$5>=$C31)*(IF(T$5=$C31,0.5,1)) -> 0
B32: Total depreciation | P32: =SUM(P26:P31) -> -29.884697 | Q32: =SUM(Q26:Q31) -> -65.787947 | R32: =SUM(R26:R31) -> -78.415345 | S32: =SUM(S26:S31) -> -91.674112 | T32: =SUM(T26:T31) -> -105.59582
B34: BOP Goodwill & trademarks | P34: =+I37 -> 2028.486 | Q34: =+P37 -> 2009.0481 | R34: =+Q37 -> 1993.1173 | S34: =+R37 -> 1980.7029 | T34: =+S37 -> 1971.821
B35: Intangible CAPEX | P35: =+Assumptions!P24*SalesOPEX!P10 -> 55.734726 | Q35: =+Assumptions!Q24*SalesOPEX!Q10 -> 58.521462 | R35: =+Assumptions!R24*SalesOPEX!R10 -> 61.447536 | S35: =+Assumptions!S24*SalesOPEX!S10 -> 64.519912 | T35: =+Assumptions!T24*SalesOPEX!T10 -> 67.745908
B36: Amortization | P36: =-I37*Assumptions!P25 -> -75.172627 | Q36: =-P37*Assumptions!Q25 -> -74.452287 | R36: =-Q37*Assumptions!R25 -> -73.861915 | S36: =-R37*Assumptions!S25 -> -73.401857 | T36: =-S37*Assumptions!T25 -> -73.072706
B37: EOP Goodwill & trademarks | I37: =Restatements!L80+Restatements!L81 -> 2028.486 | P37: =SUM(P34:P36) -> 2009.0481 | Q37: =SUM(Q34:Q36) -> 1993.1173 | R37: =SUM(R34:R36) -> 1980.7029 | S37: =SUM(S34:S36) -> 1971.821 | T37: =SUM(T34:T36) -> 1966.4942

Sheet Financing
B2: Financing Forecasts
F3: Historicals | J3: Explicit forecast
B5: =[1]AsReported!B5 -> (EUR m) | F5: =[1]AsReported!F5 -> 41639 | G5: =[1]AsReported!G5 -> 42004 | H5: =[1]AsReported!H5 -> 42369 | I5: =Investments!O5 -> 45477 | J5: =Investments!P5 -> 45842 | K5: =J5+365 -> 46207 | L5: =K5+365 -> 46572 | M5: =L5+365 -> 46937 | N5: =M5+365 -> 47302 | P5: Notes
B8: Equity forecast
A10: Output Recall | B10: Total net income | J10: =+'Output (2)'!P29 -> 163.23272 | K10: =+'Output (2)'!Q29 -> 156.92259 | L10: =+'Output (2)'!R29 -> 196.00538 | M10: =+'Output (2)'!S29 -> 204.54187 | N10: =+'Output (2)'!T29 -> 210.2589
A11: IS Output | B11: Dividends | J11: =J10*Assumptions!P35 -> 0.91926471 | K11: =K10*Assumptions!Q35 -> 0.88372848 | L11: =L10*Assumptions!R35 -> 1.1038279 | M11: =M10*Assumptions!S35 -> 1.1519022 | N11: =N10*Assumptions!T35 -> 1.1840983
B13: Evolution of retained earnings
B14: BOP retained earnings | J14: =+I17 -> 1579.887 | K14: =+J17 -> 1742.2005 | L14: =+K17 -> 1898.2393 | M14: =+L17 -> 2093.1409 | N14: =+M17 -> 2296.5308
A15: Linking Cell | B15: + Total net income | J15: =+J10 -> 163.23272 | K15: =+K10 -> 156.92259 | L15: =+L10 -> 196.00538 | M15: =+M10 -> 204.54187 | N15: =+N10 -> 210.2589
B16: - Dividends | J16: =-J11 -> -0.91926471 | K16: =-K11 -> -0.88372848 | L16: =-L11 -> -1.1038279 | M16: =-M11 -> -1.1519022 | N16: =-N11 -> -1.1840983
A17: BS Output | B17: EOP retained earnings | I17: =Restatements!L100 -> 1579.887 | J17: =+SUM(J14:J16) -> 1742.2005 | K17: =+SUM(K14:K16) -> 1898.2393 | L17: =+SUM(L14:L16) -> 2093.1409 | M17: =+SUM(M14:M16) -> 2296.5308 | N17: =+SUM(N14:N16) -> 2505.6056
A19: BS Output | B19: Minorities | I19: =Restatements!L103 -> -1.896 | J19: =+I19 -> -1.896 | K19: =+J19 -> -1.896 | L19: =+K19 -> -1.896 | M19: =+L19 -> -1.896 | N19: =+M19 -> -1.896
A20: BS Output | B20: Share capital | I20: =Restatements!L99 -> 221.031 | J20: =+I20+Assumptions!P36 -> 221.031 | K20: =+J20+Assumptions!Q36 -> 221.031 | L20: =+K20+Assumptions!R36 -> 221.031 | M20: =+L20+Assumptions!S36 -> 221.031 | N20: =+M20+Assumptions!T36 -> 221.031
B22: Debt forecast
A24: BS Output | B24: ST financial debt | J24: =+SalesOPEX!P10*Assumptions!P38 -> 32.784277 | K24: =+SalesOPEX!Q10*Assumptions!Q38 -> 34.423491 | L24: =+SalesOPEX!R10*Assumptions!R38 -> 36.144666 | M24: =+SalesOPEX!S10*Assumptions!S38 -> 37.951899 | N24: =+SalesOPEX!T10*Assumptions!T38 -> 39.849494
A25: BS Output | B25: Bonds and securities | I25: =Restatements!L94 -> 966.781 | J25: =+I25+Assumptions!P40+Assumptions!P41 -> 966.781 | K25: =+J25+Assumptions!Q40+Assumptions!Q41 -> 966.781 | L25: =+K25+Assumptions!R40+Assumptions!R41 -> 966.781 | M25: =+L25+Assumptions!S40+Assumptions!S41 -> 966.781 | N25: =+M25+Assumptions!T40+Assumptions!T41 -> 966.781
A27: IS Output | B27: Interest expenses | J27: =-AVERAGE(I28:J28)*Assumptions!P39 -> -62.04382 | K27: =-AVERAGE(J28:K28)*Assumptions!Q39 -> -61.632259 | L27: =-AVERAGE(K28:L28)*Assumptions!R39 -> -61.735774 | M27: =-AVERAGE(L28:M28)*Assumptions!S39 -> -61.844464 | N27: =-AVERAGE(M28:N28)*Assumptions!T39 -> -61.958588
B28: Gross financial debt | I28: =Restatements!L95 -> 1014.565 | J28: =SUM(J24:J25) -> 999.56528 | K28: =SUM(K24:K25) -> 1001.2045 | L28: =SUM(L24:L25) -> 1002.9257 | M28: =SUM(M24:M25) -> 1004.7329 | N28: =SUM(N24:N25) -> 1006.6305
B30: Cash balance forecast
B32: Cash / bank overdraft evolution
B33: BOP cash | J33: =+I35 -> 393.268 | K33: =+J35 -> 577.97092 | L33: =+K35 -> 742.96309 | M33: =+L35 -> 950.52288 | N33: =+M35 -> 1174.1566
A34: Output Recall | B34: + change in cash | J34: ='Output (2)'!P102 -> 184.70292 | K34: ='Output (2)'!Q102 -> 164.99217 | L34: ='Output (2)'!R102 -> 207.55978 | M34: ='Output (2)'!S102 -> 223.63371 | N34: ='Output (2)'!T102 -> 235.66949
A35: Linking Cell | B35: = EOP cash / overdraft | I35: =Restatements!L96 -> 393.268 | J35: =SUM(J33:J34) -> 577.97092 | K35: =SUM(K33:K34) -> 742.96309 | L35: =SUM(L33:L34) -> 950.52288 | M35: =SUM(M33:M34) -> 1174.1566 | N35: =SUM(N33:N34) -> 1409.8261
A37: IS Output | B37: Interest inc. (exp.) on cash (overdraft) | K37: =AVERAGE(J35:K35)*(IF(AVERAGE(J35:K35)>0,Assumptions!Q42,Assumptions!Q39)) -> 9.6914484 | L37: =AVERAGE(K35:L35)*(IF(AVERAGE(K35:L35)>0,Assumptions!R42,Assumptions!R39)) -> 12.424793 | M37: =AVERAGE(L35:M35)*(IF(AVERAGE(L35:M35)>0,Assumptions!S42,Assumptions!S39)) -> 15.58838 | N37: =AVERAGE(M35:N35)*(IF(AVERAGE(M35:N35)>0,Assumptions!T42,Assumptions!T39)) -> 18.958203

Sheet Others
B2: Taxes and Other Items Forecasts
F3: Historicals | J3: Explicit forecast
B5: =[1]AsReported!B5 -> (EUR m) | F5: =[1]AsReported!F5 -> 41639 | G5: =[1]AsReported!G5 -> 42004 | H5: =[1]AsReported!H5 -> 42369 | I5: =[1]AsReported!I5 -> 42735 | J5: =[1]AsReported!J5 -> 43100 | K5: =[1]AsReported!K5 -> 43465 | L5: =[1]AsReported!L5 -> 43830 | M5: =[1]AsReported!M5 -> 44196 | N5: =[1]AsReported!N5 -> 44561 | P5: Notes
B8: Other balance sheet items forecast
A10: BS Output | B10: Associates | I10: =Restatements!L86 -> 3.589 | J10: =+I10 -> 3.589 | K10: =+J10 -> 3.589 | L10: =+K10 -> 3.589 | M10: =+L10 -> 3.589 | N10: =+M10 -> 3.589
A11: BS Output | B11: Other non-operational assets | I11: =Restatements!L88 -> 2.701 | J11: =+I11 -> 2.701 | K11: =+J11 -> 2.701 | L11: =+K11 -> 2.701 | M11: =+L11 -> 2.701 | N11: =+M11 -> 2.701
A13: IS Output | B13: Income from associates | J13: 0 | K13: =+J13 -> 0 | L13: =+K13 -> 0 | M13: =+L13 -> 0 | N13: =+M13 -> 0
A14: IS Output | B14: Except. items | J14: 0 | K14: =+J14 -> 0 | L14: =+K14 -> 0 | M14: =+L14 -> 0 | N14: =+M14 -> 0
B16: Income taxes forecast
A18: Output Recall | B18: Income before taxes | J18: =+'Output (2)'!P26 -> 229.76659 | K18: =+'Output (2)'!Q26 -> 220.98591 | L18: =+'Output (2)'!R26 -> 275.20719 | M18: =+'Output (2)'!S26 -> 287.03861 | N18: =+'Output (2)'!T26 -> 294.98496
A19: Output Recall | B19: EBIT | J19: =+'Output (2)'!P20 -> 292.04851 | K19: =+'Output (2)'!Q20 -> 282.73588 | L19: =+'Output (2)'!R20 -> 337.23274 | M19: =+'Output (2)'!S20 -> 348.90953 | N19: =+'Output (2)'!T20 -> 357.17095
B21: - Income tax 1 on EBT (IRES) | J21: =-J18*Assumptions!P47 -> -55.143983 | K21: =-K18*Assumptions!Q47 -> -53.036619 | L21: =-L18*Assumptions!R47 -> -66.049725 | M21: =-M18*Assumptions!S47 -> -68.889266 | N21: =-N18*Assumptions!T47 -> -70.79639
B22: - Income tax 2 on EBIT (IRAP) | J22: =-J19*Assumptions!P48 -> -11.389892 | K22: =-K19*Assumptions!Q48 -> -11.026699 | L22: =-L19*Assumptions!R48 -> -13.152077 | M22: =-M19*Assumptions!S48 -> -13.607472 | N22: =-N19*Assumptions!T48 -> -13.929667
A23: IS Output | B23: - Income taxes | J23: =SUM(J21:J22) -> -66.533875 | K23: =SUM(K21:K22) -> -64.063319 | L23: =SUM(L21:L22) -> -79.201801 | M23: =SUM(M21:M22) -> -82.496738 | N23: =SUM(N21:N22) -> -84.726057

Sheet Output >>>
C12: Diasorin
C13: Financial Model
C17: Output

Sheet Output (2)
B2: Output Financial Statements
F3: Historicals | P3: Explicit forecast
B5: =[1]AsReported!B5 -> (EUR m) | F5: 42192 | G5: =F5+365 -> 42557 | H5: =G5+365 -> 42922 | I5: =H5+365 -> 43287 | J5: =I5+365 -> 43652 | K5: =J5+365 -> 44017 | L5: =K5+365 -> 44382 | M5: =L5+365 -> 44747 | N5: =M5+365 -> 45112 | ... T5: =S5+365 -> 47302 | V5: Notes
B8: Income statement
B10: Sales | F10: =Restatements!C38 -> 499.181 | G10: =Restatements!D38 -> 569.312 | H10: =Restatements!E38 -> 637.487 | I10: =Restatements!F38 -> 669.197 | J10: =Restatements!G38 -> 706.319 | K10: =Restatements!H38 -> 881.305 | L10: =Restatements!I38 -> 1237.654 | M10: =Restatements!J38 -> 1361.138 | ... O10: =Restatements!L38 -> 1185.427 | P10: =+SalesOPEX!P10 -> 1200 | Q10: =+SalesOPEX!Q10 -> 1260 | R10: =+SalesOPEX!R10 -> 1323 | S10: =+SalesOPEX!S10 -> 1389.15 | T10: =+SalesOPEX!T10 -> 1458.6075
B11: Growth | F11: n/a | G11: =G10/F10-1 -> 0.14049213 | H11: =H10/G10-1 -> 0.1197498 | I11: =I10/H10-1 -> 0.049742191 | J11: =J10/I10-1 -> 0.055472454 | K11: =K10/J10-1 -> 0.24774358 | L11: =L10/K10-1 -> 0.40434242 | M11: =M10/L10-1 -> 0.099772634 | N11: =N10/M10-1 -> -0.15643381 | O11: =O10/N10-1 -> 0.03241306 | P11: =+P10/O10-1 -> 0.01229346 | Q11: =+Q10/P10-1 -> 0.05 | R11: =+R10/Q10-1 -> 0.05 | S11: =+S10/R10-1 -> 0.05 | T11: =+T10/S10-1 -> 0.05
